Workbook

Sheet LEIA-ME
A1: TERRITÓRIOS SECTI — Amostras de dados e filtros CT&I (Bahia)
A2: Cada aba traz a amostra de um dataset citado no resumo executivo. A linha 1 de cada aba repete a descrição e o arquivo de origem; a linha 2 é o cabeçalho, com filtro.
A3: A coluna "Filtro CT&I" diz se as linhas da aba já foram selecionadas por CT&I (✅), se trazem uma coluna que classifica cada linha (🏷️), se não foram filtradas mas têm variável CT&I (🔶) ou se não há variável CT&I (⬜).
A4: A aba Filtros_CTI é a regra oficial de recorte CT&I do painel. Clique no nome de uma aba para abri-la.
A6: Aba | B6: Fonte | C6: O que retorna | D6: Recorte da amostra | E6: Filtro CT&I | F6: Variáveis CT&I | G6: Linhas | H6: Colunas | I6: Arquivo de origem
A7: Filtros_CTI | B7: Todas | C7: Lista única de filtros CT&I: fonte, campo, operador, valores, nível e justificativa | D7: — | E7: — | F7: — | G7: =COUNTA(Filtros_CTI!A:A)-2 -> 30 | H7: =COUNTA(Filtros_CTI!2:2) -> 8 | I7: categorias_cti/filtros_cti_consolidado.csv
A8: IBGE_Populacao | B8: IBGE | C8: População residente estimada por município (SIDRA 6579) | D8: 417 municípios × 2024–2026 | E8: ⬜ Sem variável | F8: — | G8: =COUNTA(IBGE_Populacao!A:A)-2 -> 1251 | H8: =COUNTA(IBGE_Populacao!2:2) -> 11 | I8: amostras/ibge_2.1_populacao_6579_BA.csv
A9: IBGE_PIB_VAB | B9: IBGE | C9: PIB e valor adicionado por setor, em mil R$ (SIDRA 5938), formato longo | D9: 417 municípios × 2022–2023 | E9: ⬜ Sem variável | F9: — | G9: =COUNTA(IBGE_PIB_VAB!A:A)-2 -> 5838 | H9: =COUNTA(IBGE_PIB_VAB!2:2) -> 11 | I9: amostras/ibge_2.2_pib_vab_5938_BA.csv
A10: IBGE_PIB_per_capita_2023 | B10: IBGE | C10: PIB e PIB per capita oficiais (base do PIB dos Municípios) | D10: 417 municípios, 2023 | E10: ⬜ Sem variável | F10: — | G10: =COUNTA(IBGE_PIB_per_capita_2023!A:A)-2 -> 417 | H10: =COUNTA(IBGE_PIB_per_capita_2023!2:2) -> 8 | I10: amostras/ibge_2.3_pib_per_capita_oficial_BA_2023.csv
A11: IBGE_Derivados | B11: IBGE | C11: PIB per capita, densidade demográfica e PIB por km² | D11: 15 municípios de referência, 2023 | E11: ⬜ Sem variável | F11: — | G11: =COUNTA(IBGE_Derivados!A:A)-2 -> 15 | H11: =COUNTA(IBGE_Derivados!2:2) -> 11 | I11: amostras/ibge_2.3_2.5_2.6_derivados_amostra_BA.csv
A12: IBGE_Area | B12: IBGE | C12: Área (km²) e centroide de cada município | D12: 417 municípios | E12: ⬜ Sem variável | F12: — | G12: =COUNTA(IBGE_Area!A:A)-2 -> 417 | H12: =COUNTA(IBGE_Area!2:2) -> 9 | I12: amostras/ibge_2.4_area_centroide_BA.csv
A13: IBGE_Malha | B13: IBGE | C13: Metadados do polígono de cada município (o GeoJSON completo fica fora da planilha) | D13: 30 municípios | E13: ⬜ Sem variável | F13: — | G13: =COUNTA(IBGE_Malha!A:A)-2 -> 30 | H13: =COUNTA(IBGE_Malha!2:2) -> 4 | I13: amostras/ibge_2.7_malha_amostra_BA.csv
A14: INEP_IES | B14: INEP | C14: Instituições de ensino superior: tipo, rede, sede, docentes por titulação | D14: 40 IES com mais doutores | E14: 🔶 Não filtrado | F14: ies_tecnologica_if_cefet (IF/CEFET); QT_DOC_EX_DOUT | G14: =COUNTA(INEP_IES!A:A)-2 -> 40 | H14: =COUNTA(INEP_IES!2:2) -> 21 | I14: amostras/inep_3.1_3.7_ies_BA_amostra.csv
A15: INEP_Cursos | B15: INEP | C15: Cursos de graduação: área CINE, grau, modalidade, vagas, matrículas, ingressantes e concluintes | D15: Estratificada: 15 STEM pres. + 5 ampliado + 5 fora + 10 STEM EAD | E15: 🏷️ Classificado | F15: nivel_cti ← CO_CINE_AREA_GERAL (05/06/07 núcleo; 08/09 ampliado) | G15: =COUNTA(INEP_Cursos!A:A)-2 -> 35 | H15: =COUNTA(INEP_Cursos!2:2) -> 27 | I15: amostras/inep_3.2_a_3.6_cursos_BA_amostra.csv
A16: INEP_Cursos_Municipio | B16: INEP | C16: Soma de cursos, vagas e matrículas presenciais por município e nível CT&I | D16: 13 municípios de referência, só presencial | E16: 🏷️ Classificado | F16: nivel_cti | G16: =COUNTA(INEP_Cursos_Municipio!A:A)-2 -> 36 | H16: =COUNTA(INEP_Cursos_Municipio!2:2) -> 8 | I16: amostras/inep_cursos_presenciais_por_municipio_nivel_cti_amostra.csv
A17: ANEEL_SIGA | B17: ANEEL | C17: Usinas de geração: tipo, fonte, fase, potência, coordenadas, município (texto) | D17: Todas as 1.163 usinas da BA | E17: 🔶 Não filtrado | F17: SigTipoGeracao ∈ {EOL, UFV} (auxiliar) | G17: =COUNTA(ANEEL_SIGA!A:A)-2 -> 1163 | H17: =COUNTA(ANEEL_SIGA!2:2) -> 23 | I17: amostras/aneel_4.1_4.2_siga_geracao_BA.csv
A18: ANEEL_INDGER | B18: ANEEL | C18: Unidades consumidoras ativas e indicadores comerciais por município e mês | D18: COELBA, 1.500 linhas (2023–2026) | E18: ⬜ Sem variável | F18: — | G18: =COUNTA(ANEEL_INDGER!A:A)-2 -> 1500 | H18: =COUNTA(ANEEL_INDGER!2:2) -> 63 | I18: amostras/aneel_4.3_indger_comercial_BA_amostra.csv
A19: ANEEL_SAMP | B19: ANEEL | C19: Mercado de energia por classe de consumo (kWh, kW, R$); sem município | D19: COELBA, 1.000 linhas (jan/2024) | E19: 🔶 Não filtrado | F19: DscDetalheMercado: energia injetada/compensada (auxiliar) | G19: =COUNTA(ANEEL_SAMP!A:A)-2 -> 1000 | H19: =COUNTA(ANEEL_SAMP!2:2) -> 18 | I19: amostras/aneel_4.3_samp_mercado_COELBA_amostra.csv
A20: ANEEL_PeD | B20: ANEEL | C20: Projetos de P&D regulado: situação, tema, fase de inovação, produto, custos | D20: 99 projetos COELBA, 2009–2026 | E20: ✅ Filtrado (dataset inteiro é CT&I) | F20: SigFasInovacaoProjeto; SigTemaProjeto; SigTipoProdutoProjeto | G20: =COUNTA(ANEEL_PeD!A:A)-2 -> 99 | H20: =COUNTA(ANEEL_PeD!2:2) -> 17 | I20: amostras/aneel_4.4_ped_projetos_COELBA.csv
A21: ANEEL_DECFEC_Conjunto | B21: ANEEL | C21: DEC e FEC anuais por conjunto elétrico, com limite regulatório | D21: 211 conjuntos COELBA, 2025 | E21: ⬜ Sem variável | F21: — | G21: =COUNTA(ANEEL_DECFEC_Conjunto!A:A)-2 -> 211 | H21: =COUNTA(ANEEL_DECFEC_Conjunto!2:2) -> 11 | I21: amostras/aneel_4.5_decfec_conjunto_BA_2025.csv
A22: ANEEL_DECFEC_Municipio | B22: ANEEL | C22: DEC e FEC por município (média dos conjuntos, ponderada por consumidores) | D22: 415 municípios, 2025 | E22: ⬜ Sem variável | F22: — | G22: =COUNTA(ANEEL_DECFEC_Municipio!A:A)-2 -> 415 | H22: =COUNTA(ANEEL_DECFEC_Municipio!2:2) -> 8 | I22: amostras/aneel_4.5_decfec_municipio_BA_2025.csv
A23: ANEEL_INDQUAL | B23: ANEEL | C23: De-para conjunto elétrico ↔ município | D23: 211 conjuntos ativos em 2025 | E23: ⬜ Sem variável | F23: — | G23: =COUNTA(ANEEL_INDQUAL!A:A)-2 -> 1262 | H23: =COUNTA(ANEEL_INDQUAL!2:2) -> 5 | I23: amostras/aneel_4.5_indqual_conjunto_municipio_BA.csv
A24: BNDES_Nao_Automaticas | B24: BNDES | C24: Operações diretas e indiretas não automáticas, com colunas de classificação CT&I | D24: 15 CT&I + 5 auxiliar + 10 fora | E24: 🏷️ Classificado | F24: inovacao; instrumento_financeiro; fonte_de_recurso_desembolsos → cti_nivel | G24: =COUNTA(BNDES_Nao_Automaticas!A:A)-2 -> 30 | H24: =COUNTA(BNDES_Nao_Automaticas!2:2) -> 44 | I24: amostras/bndes_5.x_nao_automaticas_BA_amostra.csv
A25: BNDES_Indiretas_Automaticas | B25: BNDES | C25: Operações indiretas automáticas (FINAME, BNDES Automático), com colunas CT&I | D25: 15 CT&I + 5 auxiliar + 10 fora | E25: 🏷️ Classificado | F25: inovacao; instrumento_financeiro; fonte_de_recurso_desembolsos → cti_nivel | G25: =COUNTA(BNDES_Indiretas_Automaticas!A:A)-2 -> 30 | H25: =COUNTA(BNDES_Indiretas_Automaticas!2:2) -> 40 | I25: amostras/bndes_5.x_indiretas_automaticas_BA_amostra.csv
A26: BNDES_CTI_Municipio_Ano | B26: BNDES | C26: Operações CT&I somadas por município e ano | D26: Completo: 76 municípios × anos, 2002–2026 | E26: ✅ Filtrado | F26: cti_nivel = CT&I (regra explícita) | G26: =COUNTA(BNDES_CTI_Municipio_Ano!A:A)-2 -> 131 | H26: =COUNTA(BNDES_CTI_Municipio_Ano!2:2) -> 6 | I26: amostras/bndes_5.5_cti_por_municipio_ano_BA.csv
A27: SICONFI_Receita | B27: SICONFI | C27: Receitas por conta (DCA Anexo I-C) | D27: Salvador 2024, 40 linhas | E27: ⬜ Sem variável | F27: — | G27: =COUNTA(SICONFI_Receita!A:A)-2 -> 40 | H27: =COUNTA(SICONFI_Receita!2:2) -> 11 | I27: amostras/siconfi_6.2_dca_anexoIC_receita_salvador_2024_amostra.csv
A28: SICONFI_RREO_CTI | B28: SICONFI | C28: Despesa por função/subfunção (RREO Anexo 02) | D28: Salvador 2025, 6º bimestre | E28: ✅ Filtrado (texto da conta) | F28: conta contém Ciência, Tecnol ou TOTAL | G28: =COUNTA(SICONFI_RREO_CTI!A:A)-2 -> 52 | H28: =COUNTA(SICONFI_RREO_CTI!2:2) -> 15 | I28: amostras/siconfi_6.3_rreo_anexo02_salvador_2025_cti.csv
A29: SICONFI_DCA_CTI | B29: SICONFI | C29: Despesa liquidada por município: total, Função 19, subfunções 571–573 e 126 | D29: 415 municípios, 2024 | E29: 🏷️ Classificado em colunas | F29: Função 19; subfunções 571/572/573; 126 (auxiliar) | G29: =COUNTA(SICONFI_DCA_CTI!A:A)-2 -> 415 | H29: =COUNTA(SICONFI_DCA_CTI!2:2) -> 9 | I29: amostras/siconfi_6.3_6.4_dca_IE_BA_2024_ciencia_tecnologia_por_municipio.csv
A30: ANATEL_Densidade | B30: ANATEL | C30: Acessos de banda larga fixa por 100 domicílios, por município e mês | D30: 5 municípios × 2021, 2022, 2025, 2026 | E30: ⬜ Sem variável | F30: — | G30: =COUNTA(ANATEL_Densidade!A:A)-2 -> 162 | H30: =COUNTA(ANATEL_Densidade!2:2) -> 9 | I30: amostras/anatel_7.1_densidade_scm_BA_amostra.csv
A31: ANATEL_Acessos | B31: ANATEL | C31: Acessos por prestadora, tecnologia, meio de acesso e velocidade (jan–ago/2026) | D31: 40 maiores linhas, municípios de referência | E31: 🔶 Não filtrado | F31: Meio de Acesso = Fibra; Faixa > 34Mbps (auxiliar) | G31: =COUNTA(ANATEL_Acessos!A:A)-2 -> 40 | H31: =COUNTA(ANATEL_Acessos!2:2) -> 21 | I31: amostras/anatel_acessos_bl_fixa_2026_BA_amostra.csv
A33: Fontes e datas: coleta de 01 a 07/10/2026; detalhes, regras e ressalvas em RESULTADOS_AMOSTRAGEM.md. Linhas e Colunas são fórmulas que contam o conteúdo de cada aba.

Sheet IBGE_Populacao
A1: ← LEIA-ME | B1: População residente estimada por município (SIDRA 6579) | C1: Origem: amostras/ibge_2.1_populacao_6579_BA.csv
A2: codigo_ibge | B2: variavel_id | C2: variavel | D2: unidade | E2: ano_referencia | F2: populacao | G2: municipio | H2: uf | I2: fonte | J2: url_fonte | K2: data_coleta
A3: 2900108 | B3: 9324 | C3: População residente estimada | D3: Pessoas | E3: 2024 | F3: 7452 | G3: Abaíra | H3: BA | I3: IBGE/SIDRA agregado 6579 | J3: https://servicodados.ibge.gov.br/api/v3/agregados/6579/periodos/-3/variaveis/9324?localidades=N6[N3[29]] | K3: 2026-10-05
A4: 2900108 | B4: 9324 | C4: População residente estimada | D4: Pessoas | E4: 2025 | F4: 7407 | G4: Abaíra | H4: BA | I4: IBGE/SIDRA agregado 6579 | J4: https://servicodados.ibge.gov.br/api/v3/agregados/6579/periodos/-3/variaveis/9324?localidades=N6[N3[29]] | K4: 2026-10-05
A5: 2900108 | B5: 9324 | C5: População residente estimada | D5: Pessoas | E5: 2026 | F5: 7366 | G5: Abaíra | H5: BA | I5: IBGE/SIDRA agregado 6579 | J5: https://servicodados.ibge.gov.br/api/v3/agregados/6579/periodos/-3/variaveis/9324?localidades=N6[N3[29]] | K5: 2026-10-05
A6: 2900207 | B6: 9324 | C6: População residente estimada | D6: Pessoas | E6: 2024 | F6: 18240 | G6: Abaré | H6: BA | I6: IBGE/SIDRA agregado 6579 | J6: https://servicodados.ibge.gov.br/api/v3/agregados/6579/periodos/-3/variaveis/9324?localidades=N6[N3[29]] | K6: 2026-10-05
A7: 2900207 | B7: 9324 | C7: População residente estimada | D7: Pessoas | E7: 2025 | F7: 18269 | G7: Abaré | H7: BA | I7: IBGE/SIDRA agregado 6579 | J7: https://servicodados.ibge.gov.br/api/v3/agregados/6579/periodos/-3/variaveis/9324?localidades=N6[N3[29]] | K7: 2026-10-05
A8: 2900207 | B8: 9324 | C8: População residente estimada | D8: Pessoas | E8: 2026 | F8: 18303 | G8: Abaré | H8: BA | I8: IBGE/SIDRA agregado 6579 | J8: https://servicodados.ibge.gov.br/api/v3/agregados/6579/periodos/-3/variaveis/9324?localidades=N6[N3[29]] | K8: 2026-10-05
A9: 2900306 | B9: 9324 | C9: População residente estimada | D9: Pessoas | E9: 2024 | F9: 14215 | G9: Acajutiba | H9: BA | I9: IBGE/SIDRA agregado 6579 | J9: https://servicodados.ibge.gov.br/api/v3/agregados/6579/periodos/-3/variaveis/9324?localidades=N6[N3[29]] | K9: 2026-10-05
A10: 2900306 | B10: 9324 | C10: População residente estimada | D10: Pessoas | E10: 2025 | F10: 14200 | G10: Acajutiba | H10: BA | I10: IBGE/SIDRA agregado 6579 | J10: https://servicodados.ibge.gov.br/api/v3/agregados/6579/periodos/-3/variaveis/9324?localidades=N6[N3[29]] | K10: 2026-10-05
A11: 2900306 | B11: 9324 | C11: População residente estimada | D11: Pessoas | E11: 2026 | F11: 14187 | G11: Acajutiba | H11: BA | I11: IBGE/SIDRA agregado 6579 | J11: https://servicodados.ibge.gov.br/api/v3/agregados/6579/periodos/-3/variaveis/9324?localidades=N6[N3[29]] | K11: 2026-10-05
A12: 2900355 | B12: 9324 | C12: População residente estimada | D12: Pessoas | E12: 2024 | F12: 14554 | G12: Adustina | H12: BA | I12: IBGE/SIDRA agregado 6579 | J12: https://servicodados.ibge.gov.br/api/v3/agregados/6579/periodos/-3/variaveis/9324?localidades=N6[N3[29]] | K12: 2026-10-05
A13: 2900355 | B13: 9324 | C13: População residente estimada | D13: Pessoas | E13: 2025 | F13: 14510 | G13: Adustina | H13: BA | I13: IBGE/SIDRA agregado 6579 | J13: https://servicodados.ibge.gov.br/api/v3/agregados/6579/periodos/-3/variaveis/9324?localidades=N6[N3[29]] | K13: 2026-10-05
A14: 2900355 | B14: 9324 | C14: População residente estimada | D14: Pessoas | E14: 2026 | F14: 14470 | G14: Adustina | H14: BA | I14: IBGE/SIDRA agregado 6579 | J14: https://servicodados.ibge.gov.br/api/v3/agregados/6579/periodos/-3/variaveis/9324?localidades=N6[N3[29]] | K14: 2026-10-05
... A1253: 2933604 | B1253: 9324 | C1253: População residente estimada | D1253: Pessoas | E1253: 2026 | F1253: 47056 | G1253: Xique-Xique | H1253: BA | I1253: IBGE/SIDRA agregado 6579 | J1253: https://servicodados.ibge.gov.br/api/v3/agregados/6579/periodos/-3/variaveis/9324?localidades=N6[N3[29]] | K1253: 2026-10-05

Sheet IBGE_PIB_VAB
A1: ← LEIA-ME | B1: PIB e valor adicionado por setor, em mil R$ (SIDRA 5938), formato longo | C1: Origem: amostras/ibge_2.2_pib_vab_5938_BA.csv
A2: codigo_ibge | B2: variavel_id | C2: variavel | D2: unidade | E2: ano_referencia | F2: valor | G2: municipio | H2: uf | I2: fonte | J2: url_fonte | K2: data_coleta
A3: 2900108 | B3: 37 | C3: Produto Interno Bruto a preços correntes | D3: Mil Reais | E3: 2022 | F3: 79220 | G3: Abaíra | H3: BA | I3: IBGE/SIDRA agregado 5938 | J3: https://servicodados.ibge.gov.br/api/v3/agregados/5938/periodos/-2/variaveis/37|498|513|517|6575|525|543?localidades=N6[N3[29]] | K3: 2026-10-05
A4: 2900108 | B4: 37 | C4: Produto Interno Bruto a preços correntes | D4: Mil Reais | E4: 2023 | F4: 84854 | G4: Abaíra | H4: BA | I4: IBGE/SIDRA agregado 5938 | J4: https://servicodados.ibge.gov.br/api/v3/agregados/5938/periodos/-2/variaveis/37|498|513|517|6575|525|543?localidades=N6[N3[29]] | K4: 2026-10-05
A5: 2900207 | B5: 37 | C5: Produto Interno Bruto a preços correntes | D5: Mil Reais | E5: 2022 | F5: 206162 | G5: Abaré | H5: BA | I5: IBGE/SIDRA agregado 5938 | J5: https://servicodados.ibge.gov.br/api/v3/agregados/5938/periodos/-2/variaveis/37|498|513|517|6575|525|543?localidades=N6[N3[29]] | K5: 2026-10-05
A6: 2900207 | B6: 37 | C6: Produto Interno Bruto a preços correntes | D6: Mil Reais | E6: 2023 | F6: 224239 | G6: Abaré | H6: BA | I6: IBGE/SIDRA agregado 5938 | J6: https://servicodados.ibge.gov.br/api/v3/agregados/5938/periodos/-2/variaveis/37|498|513|517|6575|525|543?localidades=N6[N3[29]] | K6: 2026-10-05
A7: 2900306 | B7: 37 | C7: Produto Interno Bruto a preços correntes | D7: Mil Reais | E7: 2022 | F7: 157504 | G7: Acajutiba | H7: BA | I7: IBGE/SIDRA agregado 5938 | J7: https://servicodados.ibge.gov.br/api/v3/agregados/5938/periodos/-2/variaveis/37|498|513|517|6575|525|543?localidades=N6[N3[29]] | K7: 2026-10-05
A8: 2900306 | B8: 37 | C8: Produto Interno Bruto a preços correntes | D8: Mil Reais | E8: 2023 | F8: 186446 | G8: Acajutiba | H8: BA | I8: IBGE/SIDRA agregado 5938 | J8: https://servicodados.ibge.gov.br/api/v3/agregados/5938/periodos/-2/variaveis/37|498|513|517|6575|525|543?localidades=N6[N3[29]] | K8: 2026-10-05
A9: 2900355 | B9: 37 | C9: Produto Interno Bruto a preços correntes | D9: Mil Reais | E9: 2022 | F9: 368395 | G9: Adustina | H9: BA | I9: IBGE/SIDRA agregado 5938 | J9: https://servicodados.ibge.gov.br/api/v3/agregados/5938/periodos/-2/variaveis/37|498|513|517|6575|525|543?localidades=N6[N3[29]] | K9: 2026-10-05
A10: 2900355 | B10: 37 | C10: Produto Interno Bruto a preços correntes | D10: Mil Reais | E10: 2023 | F10: 275494 | G10: Adustina | H10: BA | I10: IBGE/SIDRA agregado 5938 | J10: https://servicodados.ibge.gov.br/api/v3/agregados/5938/periodos/-2/variaveis/37|498|513|517|6575|525|543?localidades=N6[N3[29]] | K10: 2026-10-05
A11: 2900405 | B11: 37 | C11: Produto Interno Bruto a preços correntes | D11: Mil Reais | E11: 2022 | F11: 159896 | G11: Água Fria | H11: BA | I11: IBGE/SIDRA agregado 5938 | J11: https://servicodados.ibge.gov.br/api/v3/agregados/5938/periodos/-2/variaveis/37|498|513|517|6575|525|543?localidades=N6[N3[29]] | K11: 2026-10-05
A12: 2900405 | B12: 37 | C12: Produto Interno Bruto a preços correntes | D12: Mil Reais | E12: 2023 | F12: 174798 | G12: Água Fria | H12: BA | I12: IBGE/SIDRA agregado 5938 | J12: https://servicodados.ibge.gov.br/api/v3/agregados/5938/periodos/-2/variaveis/37|498|513|517|6575|525|543?localidades=N6[N3[29]] | K12: 2026-10-05
A13: 2900504 | B13: 37 | C13: Produto Interno Bruto a preços correntes | D13: Mil Reais | E13: 2022 | F13: 89980 | G13: Érico Cardoso | H13: BA | I13: IBGE/SIDRA agregado 5938 | J13: https://servicodados.ibge.gov.br/api/v3/agregados/5938/periodos/-2/variaveis/37|498|513|517|6575|525|543?localidades=N6[N3[29]] | K13: 2026-10-05
A14: 2900504 | B14: 37 | C14: Produto Interno Bruto a preços correntes | D14: Mil Reais | E14: 2023 | F14: 102934 | G14: Érico Cardoso | H14: BA | I14: IBGE/SIDRA agregado 5938 | J14: https://servicodados.ibge.gov.br/api/v3/agregados/5938/periodos/-2/variaveis/37|498|513|517|6575|525|543?localidades=N6[N3[29]] | K14: 2026-10-05
... A836: 2933604 | B836: 37 | C836: Produto Interno Bruto a preços correntes | D836: Mil Reais | E836: 2023 | F836: 780080 | G836: Xique-Xique | H836: BA | I836: IBGE/SIDRA agregado 5938 | J836: https://servicodados.ibge.gov.br/api/v3/agregados/5938/periodos/-2/variaveis/37|498|513|517|6575|525|543?localidades=N6[N3[29]] | K836: 2026-10-05
A837: 2900108 | B837: 498 | C837: Valor adicionado bruto a preços correntes total | E837: 2022 | G837: Abaíra | H837: BA | I837: IBGE/SIDRA agregado 5938 | J837: https://servicodados.ibge.gov.br/api/v3/agregados/5938/periodos/-2/variaveis/37|498|513|517|6575|525|543?localidades=N6[N3[29]] | K837: 2026-10-05
A838: 2900108 | B838: 498 | C838: Valor adicionado bruto a preços correntes total | E838: 2023 | G838: Abaíra | H838: BA | I838: IBGE/SIDRA agregado 5938 | J838: https://servicodados.ibge.gov.br/api/v3/agregados/5938/periodos/-2/variaveis/37|498|513|517|6575|525|543?localidades=N6[N3[29]] | K838: 2026-10-05
A839: 2900207 | B839: 498 | C839: Valor adicionado bruto a preços correntes total | E839: 2022 | G839: Abaré | H839: BA | I839: IBGE/SIDRA agregado 5938 | J839: https://servicodados.ibge.gov.br/api/v3/agregados/5938/periodos/-2/variaveis/37|498|513|517|6575|525|543?localidades=N6[N3[29]] | K839: 2026-10-05
A840: 2900207 | B840: 498 | C840: Valor adicionado bruto a preços correntes total | E840: 2023 | G840: Abaré | H840: BA | I840: IBGE/SIDRA agregado 5938 | J840: https://servicodados.ibge.gov.br/api/v3/agregados/5938/periodos/-2/variaveis/37|498|513|517|6575|525|543?localidades=N6[N3[29]] | K840: 2026-10-05
A841: 2900306 | B841: 498 | C841: Valor adicionado bruto a preços correntes total | E841: 2022 | G841: Acajutiba | H841: BA | I841: IBGE/SIDRA agregado 5938 | J841: https://servicodados.ibge.gov.br/api/v3/agregados/5938/periodos/-2/variaveis/37|498|513|517|6575|525|543?localidades=N6[N3[29]] | K841: 2026-10-05
A842: 2900306 | B842: 498 | C842: Valor adicionado bruto a preços correntes total | E842: 2023 | G842: Acajutiba | H842: BA | I842: IBGE/SIDRA agregado 5938 | J842: https://servicodados.ibge.gov.br/api/v3/agregados/5938/periodos/-2/variaveis/37|498|513|517|6575|525|543?localidades=N6[N3[29]] | K842: 2026-10-05
A843: 2900355 | B843: 498 | C843: Valor adicionado bruto a preços correntes total | E843: 2022 | G843: Adustina | H843: BA | I843: IBGE/SIDRA agregado 5938 | J843: https://servicodados.ibge.gov.br/api/v3/agregados/5938/periodos/-2/variaveis/37|498|513|517|6575|525|543?localidades=N6[N3[29]] | K843: 2026-10-05
A844: 2900355 | B844: 498 | C844: Valor adicionado bruto a preços correntes total | E844: 2023 | G844: Adustina | H844: BA | I844: IBGE/SIDRA agregado 5938 | J844: https://servicodados.ibge.gov.br/api/v3/agregados/5938/periodos/-2/variaveis/37|498|513|517|6575|525|543?localidades=N6[N3[29]] | K844: 2026-10-05
A845: 2900405 | B845: 498 | C845: Valor adicionado bruto a preços correntes total | E845: 2022 | G845: Água Fria | H845: BA | I845: IBGE/SIDRA agregado 5938 | J845: https://servicodados.ibge.gov.br/api/v3/agregados/5938/periodos/-2/variaveis/37|498|513|517|6575|525|543?localidades=N6[N3[29]] | K845: 2026-10-05
A846: 2900405 | B846: 498 | C846: Valor adicionado bruto a preços correntes total | E846: 2023 | G846: Água Fria | H846: BA | I846: IBGE/SIDRA agregado 5938 | J846: https://servicodados.ibge.gov.br/api/v3/agregados/5938/periodos/-2/variaveis/37|498|513|517|6575|525|543?localidades=N6[N3[29]] | K846: 2026-10-05
A847: 2900504 | B847: 498 | C847: Valor adicionado bruto a preços correntes total | E847: 2022 | G847: Érico Cardoso | H847: BA | I847: IBGE/SIDRA agregado 5938 | J847: https://servicodados.ibge.gov.br/api/v3/agregados/5938/periodos/-2/variaveis/37|498|513|517|6575|525|543?localidades=N6[N3[29]] | K847: 2026-10-05
A848: 2900504 | B848: 498 | C848: Valor adicionado bruto a preços correntes total | E848: 2023 | G848: Érico Cardoso | H848: BA | I848: IBGE/SIDRA agregado 5938 | J848: https://servicodados.ibge.gov.br/api/v3/agregados/5938/periodos/-2/variaveis/37|498|513|517|6575|525|543?localidades=N6[N3[29]] | K848: 2026-10-05
... A5840: 2933604 | B5840: 543 | C5840: Impostos, líquidos de subsídios, sobre produtos a preços correntes | E5840: 2023 | G5840: Xique-Xique | H5840: BA | I5840: IBGE/SIDRA agregado 5938 | J5840: https://servicodados.ibge.gov.br/api/v3/agregados/5938/periodos/-2/variaveis/37|498|513|517|6575|525|543?localidades=N6[N3[29]] | K5840: 2026-10-05

Sheet IBGE_PIB_per_capita_2023
A1: ← LEIA-ME | B1: PIB e PIB per capita oficiais (base do PIB dos Municípios) | C1: Origem: amostras/ibge_2.3_pib_per_capita_oficial_BA_2023.csv
A2: codigo_ibge | B2: municipio | C2: ano_referencia | D2: pib_mil_reais | E2: pib_per_capita_reais | F2: populacao_implicita | G2: fonte | H2: url_fonte
A3: 2900207 | B3: Abaré | C3: 2023 | D3: 224238.54 | E3: 12712.66 | F3: 17639 | G3: IBGE PIB dos Municípios (base TXT oficial) | H3: https://ftp.ibge.gov.br/Pib_Municipios/2022_2023/base/base_de_dados_2010_2023_txt.zip
A4: 2900108 | B4: Abaíra | C4: 2023 | D4: 84853.976 | E4: 11622.24 | F4: 7301 | G4: IBGE PIB dos Municípios (base TXT oficial) | H4: https://ftp.ibge.gov.br/Pib_Municipios/2022_2023/base/base_de_dados_2010_2023_txt.zip
A5: 2900306 | B5: Acajutiba | C5: 2023 | D5: 186446.17 | E5: 13515.49 | F5: 13795 | G5: IBGE PIB dos Municípios (base TXT oficial) | H5: https://ftp.ibge.gov.br/Pib_Municipios/2022_2023/base/base_de_dados_2010_2023_txt.zip
A6: 2900355 | B6: Adustina | C6: 2023 | D6: 275493.88 | E6: 19399.61 | F6: 14201 | G6: IBGE PIB dos Municípios (base TXT oficial) | H6: https://ftp.ibge.gov.br/Pib_Municipios/2022_2023/base/base_de_dados_2010_2023_txt.zip
A7: 2900603 | B7: Aiquara | C7: 2023 | D7: 75418.036 | E7: 16959.31 | F7: 4447 | G7: IBGE PIB dos Municípios (base TXT oficial) | H7: https://ftp.ibge.gov.br/Pib_Municipios/2022_2023/base/base_de_dados_2010_2023_txt.zip
A8: 2900702 | B8: Alagoinhas | C8: 2023 | D8: 5705227.5 | E8: 37769.21 | F8: 151055 | G8: IBGE PIB dos Municípios (base TXT oficial) | H8: https://ftp.ibge.gov.br/Pib_Municipios/2022_2023/base/base_de_dados_2010_2023_txt.zip
A9: 2900801 | B9: Alcobaça | C9: 2023 | D9: 439081.54 | E9: 17899.78 | F9: 24530 | G9: IBGE PIB dos Municípios (base TXT oficial) | H9: https://ftp.ibge.gov.br/Pib_Municipios/2022_2023/base/base_de_dados_2010_2023_txt.zip
A10: 2900900 | B10: Almadina | C10: 2023 | D10: 79710.606 | E10: 15276.08 | F10: 5218 | G10: IBGE PIB dos Municípios (base TXT oficial) | H10: https://ftp.ibge.gov.br/Pib_Municipios/2022_2023/base/base_de_dados_2010_2023_txt.zip
A11: 2901007 | B11: Amargosa | C11: 2023 | D11: 608765.2 | E11: 16668.91 | F11: 36521 | G11: IBGE PIB dos Municípios (base TXT oficial) | H11: https://ftp.ibge.gov.br/Pib_Municipios/2022_2023/base/base_de_dados_2010_2023_txt.zip
A12: 2901106 | B12: Amélia Rodrigues | C12: 2023 | D12: 521349.04 | E12: 21598.68 | F12: 24138 | G12: IBGE PIB dos Municípios (base TXT oficial) | H12: https://ftp.ibge.gov.br/Pib_Municipios/2022_2023/base/base_de_dados_2010_2023_txt.zip
A13: 2901155 | B13: América Dourada | C13: 2023 | D13: 198616.02 | E13: 13121.23 | F13: 15137 | G13: IBGE PIB dos Municípios (base TXT oficial) | H13: https://ftp.ibge.gov.br/Pib_Municipios/2022_2023/base/base_de_dados_2010_2023_txt.zip
A14: 2901205 | B14: Anagé | C14: 2023 | D14: 299894.81 | E14: 11789.24 | F14: 25438 | G14: IBGE PIB dos Municípios (base TXT oficial) | H14: https://ftp.ibge.gov.br/Pib_Municipios/2022_2023/base/base_de_dados_2010_2023_txt.zip
... A419: 2900504 | B419: Érico Cardoso | C419: 2023 | D419: 102934.02 | E419: 9707.09 | F419: 10604 | G419: IBGE PIB dos Municípios (base TXT oficial) | H419: https://ftp.ibge.gov.br/Pib_Municipios/2022_2023/base/base_de_dados_2010_2023_txt.zip

Sheet IBGE_Derivados
A1: ← LEIA-ME | B1: PIB per capita, densidade demográfica e PIB por km² | C1: Origem: amostras/ibge_2.3_2.5_2.6_derivados_amostra_BA.csv
A2: codigo_ibge | B2: municipio | C2: ano_referencia | D2: pib_mil_reais | E2: pib_per_capita_reais | F2: fonte_pib_per_capita | G2: area_km2 | H2: pib_por_km2_mil_reais | I2: populacao_ultimo_ano | J2: ano_populacao | K2: densidade_demografica_hab_km2
A3: 2901106 | B3: Amélia Rodrigues | C3: 2023 | D3: 521349.04 | E3: 21598.68 | F3: IBGE PIB dos Municípios (oficial) | G3: 166.872 | H3: 3124.25 | I3: 24814 | J3: 2026 | K3: 148.7
A4: 2903201 | B4: Barreiras | C4: 2023 | D4: 9499499 | E4: 59470.74 | F4: IBGE PIB dos Municípios (oficial) | G4: 8051.274 | H4: 1179.88 | I4: 172521 | J4: 2026 | K4: 21.43
A5: 2905701 | B5: Camaçari | C5: 2023 | D5: 27418878 | E5: 91283.07 | F5: IBGE PIB dos Municípios (oficial) | G5: 785.421 | H5: 34909.78 | I5: 323676 | J5: 2026 | K5: 412.11
A6: 2906006 | B6: Campo Formoso | C6: 2023 | D6: 1617786 | E6: 22665.37 | F6: IBGE PIB dos Municípios (oficial) | G6: 7161.827 | H6: 225.89 | I6: 75311 | J6: 2026 | K6: 10.52
A7: 2907202 | B7: Casa Nova | C7: 2023 | D7: 1135275.6 | E7: 15748.91 | F7: IBGE PIB dos Municípios (oficial) | G7: 9647.072 | H7: 117.68 | I7: 76416 | J7: 2026 | K7: 7.92
A8: 2910800 | B8: Feira de Santana | C8: 2023 | D8: 21846455 | E8: 35449.37 | F8: IBGE PIB dos Municípios (oficial) | G8: 1304.425 | H8: 16747.96 | I8: 663408 | J8: 2026 | K8: 508.58
A9: 2913606 | B9: Ilhéus | C9: 2023 | D9: 7234380.8 | E9: 40494.94 | F9: IBGE PIB dos Municípios (oficial) | G9: 1588.555 | H9: 4554.06 | I9: 189259 | J9: 2026 | K9: 119.14
A10: 2914802 | B10: Itabuna | C10: 2023 | D10: 5152367.1 | E10: 27595.86 | F10: IBGE PIB dos Municípios (oficial) | G10: 401.028 | H10: 12847.9 | I10: 196041 | J10: 2026 | K10: 488.85
A11: 2918407 | B11: Juazeiro | C11: 2023 | D11: 6159603.8 | E11: 25900.17 | F11: IBGE PIB dos Municípios (oficial) | G11: 6721.237 | H11: 916.44 | I11: 257616 | J11: 2026 | K11: 38.33
A12: 2919207 | B12: Lauro de Freitas | C12: 2023 | D12: 8918479.6 | E12: 43861.88 | F12: IBGE PIB dos Municípios (oficial) | G12: 57.942 | H12: 153920.81 | I12: 221023 | J12: 2026 | K12: 3814.56
A13: 2925303 | B13: Porto Seguro | C13: 2023 | D13: 5009893.7 | E13: 29763.04 | F13: IBGE PIB dos Municípios (oficial) | G13: 2285.734 | H13: 2191.81 | I13: 184087 | J13: 2026 | K13: 80.54
A14: 2927408 | B14: Salvador | C14: 2023 | D14: 76698777 | E14: 31724.15 | F14: IBGE PIB dos Municípios (oficial) | G14: 693.442 | H14: 110605.9 | I14: 2559945 | J14: 2026 | K14: 3691.65
... A17: 2933307 | B17: Vitória da Conquista | C17: 2023 | D17: 12666571 | E17: 34152.84 | F17: IBGE PIB dos Municípios (oficial) | G17: 3254.186 | H17: 3892.39 | I17: 398970 | J17: 2026 | K17: 122.6

Sheet IBGE_Area
A1: ← LEIA-ME | B1: Área (km²) e centroide de cada município | C1: Origem: amostras/ibge_2.4_area_centroide_BA.csv
A2: codigo_ibge | B2: area_km2 | C2: centroide_lon | D2: centroide_lat | E2: municipio | F2: uf | G2: fonte | H2: url_fonte | I2: data_coleta
A3: 2900108 | B3: 538.677 | C3: -41.7429 | D3: -13.2966 | E3: Abaíra | F3: BA | G3: IBGE Malhas v3 | H3: https://servicodados.ibge.gov.br/api/v3/malhas/estados/29/metadados?intrarregiao=municipio | I3: 2026-10-05
A4: 2900207 | B4: 1604.923 | C4: -39.3177 | D4: -8.8335 | E4: Abaré | F4: BA | G4: IBGE Malhas v3 | H4: https://servicodados.ibge.gov.br/api/v3/malhas/estados/29/metadados?intrarregiao=municipio | I4: 2026-10-05
A5: 2900306 | B5: 181.475 | C5: -38.0005 | D5: -11.6632 | E5: Acajutiba | F5: BA | G5: IBGE Malhas v3 | H5: https://servicodados.ibge.gov.br/api/v3/malhas/estados/29/metadados?intrarregiao=municipio | I5: 2026-10-05
A6: 2900355 | B6: 629.099 | C6: -38.0376 | D6: -10.5623 | E6: Adustina | F6: BA | G6: IBGE Malhas v3 | H6: https://servicodados.ibge.gov.br/api/v3/malhas/estados/29/metadados?intrarregiao=municipio | I6: 2026-10-05
A7: 2900405 | B7: 742.775 | C7: -38.7105 | D7: -11.8232 | E7: Água Fria | F7: BA | G7: IBGE Malhas v3 | H7: https://servicodados.ibge.gov.br/api/v3/malhas/estados/29/metadados?intrarregiao=municipio | I7: 2026-10-05
A8: 2900504 | B8: 735.249 | C8: -42.0673 | D8: -13.4002 | E8: Érico Cardoso | F8: BA | G8: IBGE Malhas v3 | H8: https://servicodados.ibge.gov.br/api/v3/malhas/estados/29/metadados?intrarregiao=municipio | I8: 2026-10-05
A9: 2900603 | B9: 167.877 | C9: -39.8809 | D9: -14.0918 | E9: Aiquara | F9: BA | G9: IBGE Malhas v3 | H9: https://servicodados.ibge.gov.br/api/v3/malhas/estados/29/metadados?intrarregiao=municipio | I9: 2026-10-05
A10: 2900702 | B10: 707.835 | C10: -38.4022 | D10: -12.1131 | E10: Alagoinhas | F10: BA | G10: IBGE Malhas v3 | H10: https://servicodados.ibge.gov.br/api/v3/malhas/estados/29/metadados?intrarregiao=municipio | I10: 2026-10-05
A11: 2900801 | B11: 1477.929 | C11: -39.4096 | D11: -17.4692 | E11: Alcobaça | F11: BA | G11: IBGE Malhas v3 | H11: https://servicodados.ibge.gov.br/api/v3/malhas/estados/29/metadados?intrarregiao=municipio | I11: 2026-10-05
A12: 2900900 | B12: 245.236 | C12: -39.6641 | D12: -14.7013 | E12: Almadina | F12: BA | G12: IBGE Malhas v3 | H12: https://servicodados.ibge.gov.br/api/v3/malhas/estados/29/metadados?intrarregiao=municipio | I12: 2026-10-05
A13: 2901007 | B13: 431.655 | C13: -39.6263 | D13: -13.0409 | E13: Amargosa | F13: BA | G13: IBGE Malhas v3 | H13: https://servicodados.ibge.gov.br/api/v3/malhas/estados/29/metadados?intrarregiao=municipio | I13: 2026-10-05
A14: 2901106 | B14: 166.872 | C14: -38.7205 | D14: -12.4212 | E14: Amélia Rodrigues | F14: BA | G14: IBGE Malhas v3 | H14: https://servicodados.ibge.gov.br/api/v3/malhas/estados/29/metadados?intrarregiao=municipio | I14: 2026-10-05
... A419: 2933604 | B419: 5079.662 | C419: -42.7801 | D419: -10.9843 | E419: Xique-Xique | F419: BA | G419: IBGE Malhas v3 | H419: https://servicodados.ibge.gov.br/api/v3/malhas/estados/29/metadados?intrarregiao=municipio | I419: 2026-10-05

Sheet IBGE_Malha
A1: ← LEIA-ME | B1: Metadados do polígono de cada município (o GeoJSON completo fica fora da planilha) | C1: Origem: amostras/ibge_2.7_malha_amostra_BA.csv
A2: codigo_ibge | B2: tipo_geometria | C2: n_vertices_aprox | D2: municipio
A3: 2900108 | B3: Polygon | C3: 23 | D3: Abaíra
A4: 2900207 | B4: Polygon | C4: 22 | D4: Abaré
A5: 2900306 | B5: Polygon | C5: 14 | D5: Acajutiba
A6: 2900355 | B6: Polygon | C6: 17 | D6: Adustina
A7: 2900405 | B7: Polygon | C7: 16 | D7: Água Fria
A8: 2900504 | B8: Polygon | C8: 26 | D8: Érico Cardoso
A9: 2900603 | B9: Polygon | C9: 13 | D9: Aiquara
A10: 2900702 | B10: Polygon | C10: 22 | D10: Alagoinhas
A11: 2900801 | B11: Polygon | C11: 23 | D11: Alcobaça
A12: 2900900 | B12: Polygon | C12: 10 | D12: Almadina
A13: 2901007 | B13: Polygon | C13: 19 | D13: Amargosa
A14: 2901106 | B14: Polygon | C14: 11 | D14: Amélia Rodrigues
... A32: 2902401 | B32: Polygon | C32: 22 | D32: Aurelino Leal

Sheet INEP_IES
A1: ← LEIA-ME | B1: Instituições de ensino superior: tipo, rede, sede, docentes por titulação | C1: Origem: amostras/inep_3.1_3.7_ies_BA_amostra.csv
A2: NU_ANO_CENSO | B2: CO_IES | C2: NO_IES | D2: SG_IES | E2: CO_MUNICIPIO_IES | F2: NO_MUNICIPIO_IES | G2: SG_UF_IES | H2: organizacao_academica | I2: categoria_administrativa | J2: ies_tecnologica_if_cefet | K2: IN_REPOSITORIO_INSTITUCIONAL | L2: IN_ACESSO_PORTAL_CAPES | M2: QT_DOC_TOTAL | N2: QT_DOC_EXE | O2: QT_DOC_EX_DOUT | P2: QT_DOC_EX_MEST | Q2: QT_DOC_EX_ESP | R2: QT_DOC_EX_GRAD | S2: QT_DOC_EX_INT_DE | T2: QT_TEC_DOUTORADO_FEM | U2: QT_TEC_DOUTORADO_MASC
A3: 2024 | B3: 578 | C3: UNIVERSIDADE FEDERAL DA BAHIA | D3: UFBA | E3: 2927408 | F3: Salvador | G3: BA | H3: Universidade | I3: Pública Federal | J3: FALSE | K3: 1 | L3: 1 | M3: 3131 | N3: 3131 | O3: 2466 | P3: 400 | Q3: 63 | R3: 202 | S3: 2127 | T3: 74 | U3: 45
A4: 2024 | B4: 40 | C4: UNIVERSIDADE DO ESTADO DA BAHIA | D4: UNEB | E4: 2927408 | F4: Salvador | G4: BA | H4: Universidade | I4: Pública Estadual | J4: FALSE | K4: 1 | L4: 1 | M4: 1681 | N4: 1681 | O4: 1093 | P4: 583 | Q4: 5 | R4: 0 | S4: 911 | T4: 37 | U4: 10
A5: 2024 | B5: 688 | C5: UNIVERSIDADE ESTADUAL DO SUDOESTE DA BAHIA | D5: UESB | E5: 2933307 | F5: Vitória da Conquista | G5: BA | H5: Universidade | I5: Pública Estadual | J5: FALSE | K5: 1 | L5: 1 | M5: 1034 | N5: 1034 | O5: 708 | P5: 235 | Q5: 89 | R5: 2 | S5: 742 | T5: 9 | U5: 9
A6: 2024 | B6: 4503 | C6: UNIVERSIDADE FEDERAL DO RECÔNCAVO DA BAHIA | D6: UFRB | E6: 2909802 | F6: Cruz das Almas | G6: BA | H6: Universidade | I6: Pública Federal | J6: FALSE | K6: 1 | L6: 1 | M6: 1020 | N6: 1020 | O6: 702 | P6: 243 | Q6: 31 | R6: 44 | S6: 859 | T6: 16 | U6: 14
A7: 2024 | B7: 666 | C7: UNIVERSIDADE ESTADUAL DE FEIRA DE SANTANA | D7: UEFS | E7: 2910800 | F7: Feira de Santana | G7: BA | H7: Universidade | I7: Pública Estadual | J7: FALSE | K7: 0 | L7: 1 | M7: 851 | N7: 851 | O7: 611 | P7: 199 | Q7: 40 | R7: 1 | S7: 447 | T7: 30 | U7: 20
A8: 2024 | B8: 24 | C8: UNIVERSIDADE ESTADUAL DE SANTA CRUZ | D8: UESC | E8: 2913606 | F8: Ilhéus | G8: BA | H8: Universidade | I8: Pública Estadual | J8: FALSE | K8: 0 | L8: 1 | M8: 820 | N8: 820 | O8: 603 | P8: 176 | Q8: 38 | R8: 3 | S8: 642 | T8: 11 | U8: 6
A9: 2024 | B9: 599 | C9: INSTITUTO FEDERAL DE EDUCAÇÃO, CIÊNCIA E TECNOLOGIA DA BAHIA | D9: IFBA | E9: 2927408 | F9: Salvador | G9: BA | H9: Instituto Federal de Educação, Ciência e Tecnologia | I9: Pública Federal | J9: TRUE | K9: 1 | L9: 1 | M9: 895 | N9: 895 | O9: 370 | P9: 418 | Q9: 107 | R9: 0 | S9: 756 | T9: 17 | U9: 6
A10: 2024 | B10: 18506 | C10: UNIVERSIDADE FEDERAL DO OESTE DA BAHIA | D10: UFOB | E10: 2903201 | F10: Barreiras | G10: BA | H10: Universidade | I10: Pública Federal | J10: FALSE | K10: 1 | L10: 1 | M10: 411 | N10: 411 | O10: 296 | P10: 72 | Q10: 29 | R10: 14 | S10: 328 | T10: 3 | U10: 0
A11: 2024 | B11: 534 | C11: ESCOLA BAHIANA DE MEDICINA E SAÚDE PÚBLICA | D11: EBMSP | E11: 2927408 | F11: Salvador | G11: BA | H11: Faculdade | I11: Privada sem fins lucrativos | J11: FALSE | K11: 1 | L11: 1 | M11: 518 | N11: 518 | O11: 274 | P11: 193 | Q11: 51 | R11: 0 | S11: 0 | T11: 1 | U11: 1
A12: 2024 | B12: 18812 | C12: UNIVERSIDADE FEDERAL DO SUL DA BAHIA | D12: UFSB | E12: 2914802 | F12: Itabuna | G12: BA | H12: Universidade | I12: Pública Federal | J12: FALSE | K12: 0 | L12: 1 | M12: 335 | N12: 335 | O12: 266 | P12: 43 | Q12: 26 | R12: 0 | S12: 261 | T12: 5 | U12: 4
A13: 2024 | B13: 14509 | C13: INSTITUTO FEDERAL DE EDUCAÇÃO, CIÊNCIA E TECNOLOGIA BAIANO | D13: IFBAIANO | E13: 2927408 | F13: Salvador | G13: BA | H13: Instituto Federal de Educação, Ciência e Tecnologia | I13: Pública Federal | J13: TRUE | K13: 1 | L13: 1 | M13: 434 | N13: 434 | O13: 217 | P13: 170 | Q13: 31 | R13: 16 | S13: 405 | T13: 18 | U13: 13
A14: 2024 | B14: 1883 | C14: CENTRO UNIVERSITÁRIO UNIME | D14: UNIME | E14: 2919207 | F14: Lauro de Freitas | G14: BA | H14: Centro Universitário | I14: Privada com fins lucrativos | J14: FALSE | K14: 1 | L14: 0 | M14: 441 | N14: 441 | O14: 124 | P14: 152 | Q14: 165 | R14: 0 | S14: 0 | T14: 0 | U14: 0
... A21: 2024 | B21: 1461 | C21: Centro Universitário Zarns - Salvador | D21: ZARNS SALVADOR | E21: 2927408 | F21: Salvador | G21: BA | H21: Centro Universitário | I21: Privada com fins lucrativos | J21: FALSE | K21: 1 | L21: 0 | M21: 122 | N21: 122 | O21: 66 | P21: 55 | Q21: 1 | R21: 0 | S21: 0 | T21: 2 | U21: 0
A22: 2024 | B22: 3034 | C22: Faculdade Anhanguera Unime de Salvador | E22: 2927408 | F22: Salvador | G22: BA | H22: Faculdade | I22: Privada com fins lucrativos | J22: FALSE | K22: 1 | L22: 0 | M22: 188 | N22: 188 | O22: 61 | P22: 74 | Q22: 53 | R22: 0 | S22: 0 | T22: 0 | U22: 0
A23: 2024 | B23: 18708 | C23: Faculdade AGES de Senhor do Bonfim | D23: Faculdade AGES | E23: 2930105 | F23: Senhor do Bonfim | G23: BA | H23: Faculdade | I23: Privada com fins lucrativos | J23: FALSE | K23: 1 | L23: 0 | M23: 232 | N23: 232 | O23: 57 | P23: 128 | Q23: 47 | R23: 0 | S23: 0 | T23: 0 | U23: 0
A24: 2024 | B24: 2402 | C24: Centro Universitário UNIFTC | E24: 2927408 | F24: Salvador | G24: BA | H24: Centro Universitário | I24: Privada com fins lucrativos | J24: FALSE | K24: 1 | L24: 1 | M24: 239 | N24: 239 | O24: 52 | P24: 125 | Q24: 62 | R24: 0 | S24: 0 | T24: 0 | U24: 0
A25: 2024 | B25: 2560 | C25: FACULDADE DE ENSINO SUPERIOR DA CIDADE DE FEIRA DE SANTANA | D25: FAESF/UNEF | E25: 2910800 | F25: Feira de Santana | G25: BA | H25: Faculdade | I25: Privada com fins lucrativos | J25: FALSE | K25: 1 | L25: 0 | M25: 122 | N25: 122 | O25: 50 | P25: 72 | Q25: 0 | R25: 0 | S25: 1 | T25: 0 | U25: 0
A26: 2024 | B26: 2944 | C26: FACULDADE ANHANGUERA DE ITABUNA | E26: 2914802 | F26: Itabuna | G26: BA | H26: Faculdade | I26: Privada com fins lucrativos | J26: FALSE | K26: 1 | L26: 0 | M26: 141 | N26: 141 | O26: 50 | P26: 41 | Q26: 50 | R26: 0 | S26: 0 | T26: 0 | U26: 0
A27: 2024 | B27: 2437 | C27: FACULDADE ANHANGUERA DE TEIXEIRA DE FREITAS | E27: 2931350 | F27: Teixeira de Freitas | G27: BA | H27: Faculdade | I27: Privada com fins lucrativos | J27: FALSE | K27: 1 | L27: 0 | M27: 109 | N27: 109 | O27: 46 | P27: 25 | Q27: 38 | R27: 0 | S27: 0 | T27: 0 | U27: 0
A28: 2024 | B28: 1718 | C28: CENTRO UNIVERSITÁRIO NOBRE DE FEIRA DE SANTANA | E28: 2910800 | F28: Feira de Santana | G28: BA | H28: Centro Universitário | I28: Privada com fins lucrativos | J28: FALSE | K28: 1 | L28: 0 | M28: 127 | N28: 127 | O28: 45 | P28: 82 | Q28: 0 | R28: 0 | S28: 0 | T28: 2 | U28: 0
A29: 2024 | B29: 396 | C29: Centro Universitário Ruy Barbosa Wyden | D29: UniRuy Wyden | E29: 2927408 | F29: Salvador | G29: BA | H29: Centro Universitário | I29: Privada com fins lucrativos | J29: FALSE | K29: 0 | L29: 0 | M29: 98 | N29: 98 | O29: 45 | P29: 42 | Q29: 11 | R29: 0 | S29: 0 | T29: 1 | U29: 0
A30: 2024 | B30: 1053 | C30: Centro Universitário de Excelência | D30: UNEX | E30: 2910800 | F30: Feira de Santana | G30: BA | H30: Centro Universitário | I30: Privada com fins lucrativos | J30: FALSE | K30: 1 | L30: 1 | M30: 147 | N30: 147 | O30: 43 | P30: 68 | Q30: 36 | R30: 0 | S30: 0 | T30: 1 | U30: 0
A31: 2024 | B31: 3588 | C31: CENTRO UNIVERSITÁRIO DOM PEDRO II | D31: UNIDOMPEDRO | E31: 2927408 | F31: Salvador | G31: BA | H31: Centro Universitário | I31: Privada com fins lucrativos | J31: FALSE | K31: 0 | L31: 0 | M31: 209 | N31: 209 | O31: 38 | P31: 68 | Q31: 103 | R31: 0 | S31: 0 | T31: 1 | U31: 1
A32: 2024 | B32: 4959 | C32: FACULDADE ANHANGUERA DE FEIRA DE SANTANA | E32: 2910800 | F32: Feira de Santana | G32: BA | H32: Faculdade | I32: Privada com fins lucrativos | J32: FALSE | K32: 1 | L32: 0 | M32: 61 | N32: 61 | O32: 38 | P32: 10 | Q32: 13 | R32: 0 | S32: 0 | T32: 0 | U32: 0
A33: 2024 | B33: 18625 | C33: Faculdade Anhanguera De Vitória Da Conquista | E33: 2933307 | F33: Vitória da Conquista | G33: BA | H33: Faculdade | I33: Privada com fins lucrativos | J33: FALSE | K33: 1 | L33: 0 | M33: 74 | N33: 74 | O33: 37 | P33: 16 | Q33: 21 | R33: 0 | S33: 0 | T33: 0 | U33: 0
A34: 2024 | B34: 2023 | C34: Centro Universitário FG | D34: UNIFG | E34: 2911709 | F34: Guanambi | G34: BA | H34: Centro Universitário | I34: Privada com fins lucrativos | J34: FALSE | K34: 1 | L34: 1 | M34: 131 | N34: 131 | O34: 36 | P34: 46 | Q34: 49 | R34: 0 | S34: 0 | T34: 1 | U34: 1
A35: 2024 | B35: 19260 | C35: FACULDADE ANHANGUERA DE JEQUIÉ | D35: FPJ | E35: 2918001 | F35: Jequié | G35: BA | H35: Faculdade | I35: Privada com fins lucrativos | J35: FALSE | K35: 1 | L35: 0 | M35: 65 | N35: 65 | O35: 35 | P35: 9 | Q35: 21 | R35: 0 | S35: 0 | T35: 0 | U35: 0
A36: 2024 | B36: 21553 | C36: FACULDADE ANHANGUERA DE SANTO ANTÔNIO DE JESUS | E36: 2928703 | F36: Santo Antônio de Jesus | G36: BA | H36: Faculdade | I36: Privada com fins lucrativos | J36: FALSE | K36: 1 | L36: 0 | M36: 67 | N36: 67 | O36: 34 | P36: 8 | Q36: 25 | R36: 0 | S36: 0 | T36: 0 | U36: 0
A37: 2024 | B37: 2474 | C37: CENTRO UNIVERSITÁRIO MARIA MILZA | D37: UNIMAM | E37: 2909802 | F37: Cruz das Almas | G37: BA | H37: Centro Universitário | I37: Privada com fins lucrativos | J37: FALSE | K37: 1 | L37: 1 | M37: 220 | N37: 220 | O37: 33 | P37: 126 | Q37: 61 | R37: 0 | S37: 0 | T37: 9 | U37: 3
A38: 2024 | B38: 1055 | C38: Centro Universitário Maurício de Nassau de Salvador | D38: Uninassau Salvador | E38: 2927408 | F38: Salvador | G38: BA | H38: Centro Universitário | I38: Privada sem fins lucrativos | J38: FALSE | K38: 1 | L38: 0 | M38: 114 | N38: 114 | O38: 31 | P38: 62 | Q38: 21 | R38: 0 | S38: 0 | T38: 4 | U38: 0
A39: 2024 | B39: 1643 | C39: FACULDADE ANÍSIO TEIXEIRA DE FEIRA DE SANTANA | D39: FAT | E39: 2910800 | F39: Feira de Santana | G39: BA | H39: Centro Universitário | I39: Privada sem fins lucrativos | J39: FALSE | K39: 1 | L39: 1 | M39: 191 | N39: 191 | O39: 30 | P39: 104 | Q39: 57 | R39: 0 | S39: 0 | T39: 1 | U39: 2
A40: 2024 | B40: 2222 | C40: Centro Universitário do Rio São Francisco Unirios | D40: UNIRIOS | E40: 2924009 | F40: Paulo Afonso | G40: BA | H40: Centro Universitário | I40: Privada com fins lucrativos | J40: FALSE | K40: 1 | L40: 0 | M40: 108 | N40: 108 | O40: 29 | P40: 58 | Q40: 21 | R40: 0 | S40: 3 | T40: 0 | U40: 0
A41: 2024 | B41: 3365 | C41: Faculdade UniBRAS Juazeiro | D41: FACBRAS | E41: 2918407 | F41: Juazeiro | G41: BA | H41: Faculdade | I41: Privada com fins lucrativos | J41: FALSE | K41: 0 | L41: 0 | M41: 41 | N41: 41 | O41: 26 | P41: 15 | Q41: 0 | R41: 0 | S41: 0 | T41: 1 | U41: 0
A42: 2024 | B42: 3864 | C42: Centro Universitário UNIRB - Alagoinhas | E42: 2900702 | F42: Alagoinhas | G42: BA | H42: Centro Universitário | I42: Privada com fins lucrativos | J42: FALSE | K42: 1 | L42: 1 | M42: 52 | N42: 52 | O42: 25 | P42: 27 | Q42: 0 | R42: 0 | S42: 0 | T42: 0 | U42: 0

Sheet INEP_Cursos
A1: ← LEIA-ME | B1: Cursos de graduação: área CINE, grau, modalidade, vagas, matrículas, ingressantes e concluintes | C1: Origem: amostras/inep_3.2_a_3.6_cursos_BA_amostra.csv
A2: NU_ANO_CENSO | B2: CO_IES | C2: NO_IES | D2: CO_CURSO | E2: NO_CURSO | F2: CO_MUNICIPIO | G2: NO_MUNICIPIO | H2: SG_UF | I2: modalidade | J2: dimensao | K2: grau_academico | L2: CO_CINE_AREA_GERAL | M2: NO_CINE_AREA_GERAL | N2: CO_CINE_AREA_ESPECIFICA | O2: NO_CINE_AREA_ESPECIFICA | P2: CO_CINE_AREA_DETALHADA | Q2: NO_CINE_AREA_DETALHADA | R2: CO_CINE_ROTULO | S2: NO_CINE_ROTULO | T2: nivel_cti | U2: QT_CURSO | V2: QT_VG_TOTAL | W2: QT_VG_TOTAL_EAD | X2: QT_INSCRITO_TOTAL | Y2: QT_ING | Z2: QT_MAT | AA2: QT_CONC
A3: 2024 | B3: 1883 | C3: CENTRO UNIVERSITÁRIO UNIME | D3: 1322107 | E3: Engenharia Química | F3: 2919207 | G3: Lauro de Freitas | H3: BA | I3: Presencial | J3: Presencial (município de oferta) | K3: Bacharelado | L3: 07 | M3: Engenharia, produção e construção | N3: 071 | O3: Engenharia e profissões correlatas | P3: 0711 | Q3: Engenharia química e de processos | R3: 0711E05 | S3: Engenharia química | T3: CT&I núcleo (STEM) | U3: 1 | V3: 0 | W3: 0 | X3: 0 | Y3: 0 | Z3: 6 | AA3: 2
A4: 2024 | B4: 2437 | C4: FACULDADE ANHANGUERA DE TEIXEIRA DE FREITAS | D4: 73519 | E4: Ciência Da Computação | F4: 2931350 | G4: Teixeira de Freitas | H4: BA | I4: Presencial | J4: Presencial (município de oferta) | K4: Bacharelado | L4: 06 | M4: Computação e Tecnologias da Informação e Comunicação (TIC) | N4: 061 | O4: Computação e Tecnologias da Informação e Comunicação (TIC) | P4: 0613 | Q4: Análise e desenvolvimento de algoritmos e aplicações | R4: 0613C01 | S4: Ciência da computação | T4: CT&I núcleo (STEM) | U4: 1 | V4: 0 | W4: 0 | X4: 0 | Y4: 0 | Z4: 2 | AA4: 1
A5: 2024 | B5: 3962 | C5: UNIVERSIDADE SENAI CIMATEC | D5: 1151355 | E5: Engenharia De Controle E Automação | F5: 2927408 | G5: Salvador | H5: BA | I5: Presencial | J5: Presencial (município de oferta) | K5: Bacharelado | L5: 07 | M5: Engenharia, produção e construção | N5: 071 | O5: Engenharia e profissões correlatas | P5: 0714 | Q5: Eletrônica e automação | R5: 0714E05 | S5: Engenharia de controle e automação | T5: CT&I núcleo (STEM) | U5: 1 | V5: 80 | W5: 0 | X5: 201 | Y5: 25 | Z5: 97 | AA5: 19
A6: 2024 | B6: 396 | C6: Centro Universitário Ruy Barbosa Wyden | D6: 1258415 | E6: Engenharia De Controle E Automação | F6: 2927408 | G6: Salvador | H6: BA | I6: Presencial | J6: Presencial (município de oferta) | K6: Bacharelado | L6: 07 | M6: Engenharia, produção e construção | N6: 071 | O6: Engenharia e profissões correlatas | P6: 0714 | Q6: Eletrônica e automação | R6: 0714E05 | S6: Engenharia de controle e automação | T6: CT&I núcleo (STEM) | U6: 1 | V6: 607 | W6: 0 | X6: 5 | Y6: 4 | Z6: 20 | AA6: 6
A7: 2024 | B7: 396 | C7: Centro Universitário Ruy Barbosa Wyden | D7: 1070727 | E7: Manutenção Industrial | F7: 2927408 | G7: Salvador | H7: BA | I7: Presencial | J7: Presencial (município de oferta) | K7: Tecnológico | L7: 07 | M7: Engenharia, produção e construção | N7: 071 | O7: Engenharia e profissões correlatas | P7: 0715 | Q7: Engenharia mecânica e metalurgia | R7: 0715M01 | S7: Manutenção industrial | T7: CT&I núcleo (STEM) | U7: 1 | V7: 0 | W7: 0 | X7: 0 | Y7: 0 | Z7: 0 | AA7: 0
A8: 2024 | B8: 385 | C8: UNIVERSIDADE SALVADOR | D8: 1258708 | E8: Engenharia De Petróleo | F8: 2927408 | G8: Salvador | H8: BA | I8: Presencial | J8: Presencial (município de oferta) | K8: Bacharelado | L8: 07 | M8: Engenharia, produção e construção | N8: 072 | O8: Produção e processamento | P8: 0724 | Q8: Mineração e extração | R8: 0724E02 | S8: Engenharia de petróleo | T8: CT&I núcleo (STEM) | U8: 1 | V8: 0 | W8: 0 | X8: 0 | Y8: 0 | Z8: 0 | AA8: 0
A9: 2024 | B9: 24 | C9: UNIVERSIDADE ESTADUAL DE SANTA CRUZ | D9: 150314 | E9: Engenharia Civil | F9: 2913606 | G9: Ilhéus | H9: BA | I9: Presencial | J9: Presencial (município de oferta) | K9: Bacharelado | L9: 07 | M9: Engenharia, produção e construção | N9: 073 | O9: Arquitetura e construção | P9: 0732 | Q9: Engenharia civil e construção | R9: 0732E01 | S9: Engenharia civil | T9: CT&I núcleo (STEM) | U9: 1 | V9: 70 | W9: 0 | X9: 211 | Y9: 46 | Z9: 162 | AA9: 9
A10: 2024 | B10: 3984 | C10: FUNDAÇÃO UNIVERSIDADE FEDERAL DO VALE DO SÃO FRANCISCO | D10: 1661974 | E10: Geologia | F10: 2930105 | G10: Senhor do Bonfim | H10: BA | I10: Presencial | J10: Presencial (município de oferta) | K10: Bacharelado | L10: 05 | M10: Ciências naturais, matemática e estatística | N10: 053 | O10: Ciências físicas | P10: 0532 | Q10: Ciências da terra | R10: 0532G02 | S10: Geologia | T10: CT&I núcleo (STEM) | U10: 1 | V10: 40 | W10: 0 | X10: 40 | Y10: 35 | Z10: 0 | AA10: 0
A11: 2024 | B11: 2222 | C11: Centro Universitário do Rio São Francisco Unirios | D11: 73140 | E11: Sistema De Informação | F11: 2924009 | G11: Paulo Afonso | H11: BA | I11: Presencial | J11: Presencial (município de oferta) | K11: Bacharelado | L11: 06 | M11: Computação e Tecnologias da Informação e Comunicação (TIC) | N11: 061 | O11: Computação e Tecnologias da Informação e Comunicação (TIC) | P11: 0613 | Q11: Análise e desenvolvimento de algoritmos e aplicações | R11: 0613S01 | S11: Sistemas de informação | T11: CT&I núcleo (STEM) | U11: 1 | V11: 130 | W11: 0 | X11: 104 | Y11: 104 | Z11: 201 | AA11: 11
A12: 2024 | B12: 2023 | C12: Centro Universitário FG | D12: 1489887 | E12: Análise E Desenvolvimento De Sistemas | F12: 2911709 | G12: Guanambi | H12: BA | I12: Presencial | J12: Presencial (município de oferta) | K12: Tecnológico | L12: 06 | M12: Computação e Tecnologias da Informação e Comunicação (TIC) | N12: 061 | O12: Computação e Tecnologias da Informação e Comunicação (TIC) | P12: 0613 | Q12: Análise e desenvolvimento de algoritmos e aplicações | R12: 0613S01 | S12: Sistemas de informação | T12: CT&I núcleo (STEM) | U12: 1 | V12: 45 | W12: 0 | X12: 105 | Y12: 45 | Z12: 80 | AA12: 12
A13: 2024 | B13: 10058 | C13: FACULDADE DA FRATERNIDADE DE VALENÇA | D13: 1204205 | E13: Engenharia Civil | F13: 2932903 | G13: Valença | H13: BA | I13: Presencial | J13: Presencial (município de oferta) | K13: Bacharelado | L13: 07 | M13: Engenharia, produção e construção | N13: 073 | O13: Arquitetura e construção | P13: 0732 | Q13: Engenharia civil e construção | R13: 0732E01 | S13: Engenharia civil | T13: CT&I núcleo (STEM) | U13: 1 | V13: 304 | W13: 0 | X13: 304 | Y13: 6 | Z13: 6 | AA13: 0
A14: 2024 | B14: 385 | C14: UNIVERSIDADE SALVADOR | D14: 1404804 | E14: Análise E Desenvolvimento De Sistemas | F14: 2927408 | G14: Salvador | H14: BA | I14: Presencial | J14: Presencial (município de oferta) | K14: Tecnológico | L14: 06 | M14: Computação e Tecnologias da Informação e Comunicação (TIC) | N14: 061 | O14: Computação e Tecnologias da Informação e Comunicação (TIC) | P14: 0613 | Q14: Análise e desenvolvimento de algoritmos e aplicações | R14: 0613S01 | S14: Sistemas de informação | T14: CT&I núcleo (STEM) | U14: 1 | V14: 17 | W14: 0 | X14: 45 | Y14: 17 | Z14: 61 | AA14: 22
... A37: 2024 | B37: 298 | C37: Universidade Pitágoras Unopar Anhanguera | D37: 1548987 | E37: Arquitetura De Dados | F37: 2925303 | G37: Porto Seguro | H37: BA | I37: EAD | J37: EAD ofertado no Brasil (por município/polo) | K37: Tecnológico | L37: 06 | M37: Computação e Tecnologias da Informação e Comunicação (TIC) | N37: 061 | O37: Computação e Tecnologias da Informação e Comunicação (TIC) | P37: 0612 | Q37: Infraestrutura e gestão de TIC | R37: 0612B01 | S37: Banco de dados | T37: CT&I núcleo (STEM) | U37: 0 | V37: 0 | W37: 0 | X37: 0 | Y37: 3 | Z37: 3 | AA37: 1

Sheet INEP_Cursos_Municipio
A1: ← LEIA-ME | B1: Soma de cursos, vagas e matrículas presenciais por município e nível CT&I | C1: Origem: amostras/inep_cursos_presenciais_por_municipio_nivel_cti_amostra.csv
A2: CO_MUNICIPIO | B2: NO_MUNICIPIO | C2: nivel_cti | D2: QT_CURSO | E2: QT_VG_TOTAL | F2: QT_MAT | G2: QT_ING | H2: QT_CONC
A3: 2903201 | B3: Barreiras | C3: CT&I ampliado | D3: 21 | E3: 3040 | F3: 4018 | G3: 1115 | H3: 569
A4: 2903201 | B4: Barreiras | C4: CT&I núcleo (STEM) | D4: 13 | E4: 687 | F4: 949 | G4: 273 | H4: 138
A5: 2903201 | B5: Barreiras | C5: Fora de CT&I | D5: 25 | E5: 2008 | F5: 3356 | G5: 1052 | H5: 378
A6: 2905701 | B6: Camaçari | C6: CT&I ampliado | D6: 5 | E6: 193 | F6: 97 | G6: 48 | H6: 17
A7: 2905701 | B7: Camaçari | C7: CT&I núcleo (STEM) | D7: 6 | E7: 305 | F7: 424 | G7: 160 | H7: 47
A8: 2905701 | B8: Camaçari | C8: Fora de CT&I | D8: 11 | E8: 833 | F8: 1350 | G8: 451 | H8: 207
A9: 2907202 | B9: Casa Nova | C9: Fora de CT&I | D9: 1 | E9: 223 | F9: 99 | G9: 18 | H9: 31
A10: 2910800 | B10: Feira de Santana | C10: CT&I ampliado | D10: 57 | E10: 10656 | F10: 8847 | G10: 2771 | H10: 1321
A11: 2910800 | B11: Feira de Santana | C11: CT&I núcleo (STEM) | D11: 45 | E11: 4532 | F11: 3841 | G11: 1137 | H11: 506
A12: 2910800 | B12: Feira de Santana | C12: Fora de CT&I | D12: 71 | E12: 9057 | F12: 12983 | G12: 4362 | H12: 1792
A13: 2913606 | B13: Ilhéus | C13: CT&I ampliado | D13: 13 | E13: 1390 | F13: 2197 | G13: 529 | H13: 344
A14: 2913606 | B14: Ilhéus | C14: CT&I núcleo (STEM) | D14: 13 | E14: 1168 | F14: 1815 | G14: 524 | H14: 163
... A38: 2933307 | B38: Vitória da Conquista | C38: Fora de CT&I | D38: 41 | E38: 6247 | F38: 8850 | G38: 2851 | H38: 1163

Sheet ANEEL_SIGA
A1: ← LEIA-ME | B1: Usinas de geração: tipo, fonte, fase, potência, coordenadas, município (texto) | C1: Origem: amostras/aneel_4.1_4.2_siga_geracao_BA.csv
A2: DatGeracaoConjuntoDados | B2: NomEmpreendimento | C2: IdeNucleoCEG | D2: CodCEG | E2: SigUFPrincipal | F2: SigTipoGeracao | G2: DscFaseUsina | H2: DscOrigemCombustivel | I2: DscFonteCombustivel | J2: DscTipoOutorga | K2: NomFonteCombustivel | L2: DatEntradaOperacao | M2: MdaPotenciaOutorgadaKw | N2: MdaPotenciaFiscalizadaKw | O2: MdaGarantiaFisicaKw | P2: IdcGeracaoQualificada | Q2: NumCoordNEmpreendimento | R2: NumCoordEEmpreendimento | S2: DatInicioVigencia | T2: DatFimVigencia | U2: DscPropriRegimePariticipacao | V2: DscSubBacia | W2: DscMuninicpios
A3: 2026-10-01 | B3: Bahia Pulp (Antiga Bacell) | C3: 000182 | D3: UTE.FL.BA.000182-1.1 | E3: BA | F3: UTE | G3: Operação | H3: Biomassa | I3: Floresta | J3: Autorização | K3: Licor Negro | L3: 1995-11-29 | M3: 108600 | N3: 108600 | O3: 300 | P3: Não | Q3: -12.643082 | R3: -38.337171 | S3: 2026-08-04 | T3: 2061-08-04 | U3: 100% para BRACELL BAHIA SPECIALTY CELLULOSE S.A. - 69.037.133/0001-39 (PIE) | W3: Camaçari - BA
A4: 2026-10-01 | B4: Suzano Mucuri (Antiga Bahia Sul) | C4: 000187 | D4: UTE.FL.BA.000187-2.1 | E4: BA | F4: UTE | G4: Operação | H4: Biomassa | I4: Floresta | J4: Autorização | K4: Licor Negro | L4: 1992-03-01 | M4: 214080 | N4: 214080 | O4: 0 | P4: Não | Q4: -18.042462 | R4: -39.919661 | S4: 2011-04-14 | T4: 2041-04-14 | U4: 100% para SUZANO S.A. - 16.404.287/0001-55 (APE) | W4: Mucuri - BA
A5: 2026-10-01 | B5: Camaçari | C5: 000602 | D5: UTE.GN.BA.000602-5.1 | E5: BA | F5: UTE | G5: Operação | H5: Fóssil | I5: Gás natural | J5: Autorização | K5: Gás Natural | L5: 1996-01-01 | M5: 130710 | N5: 130710 | O5: 0 | P5: Sim | Q5: -12.687227 | R5: -38.352569 | S5: 1996-10-16 | T5: 2026-10-16 | U5: 100% para Braskem S/A - 42.150.391/0001-70 (PIE) | W5: Camaçari - BA
A6: 2026-10-01 | B6: Fazenda Cachoeira | C6: 000939 | D6: UTE.PE.BA.000939-3.1 | E6: BA | F6: UTE | G6: Operação | H6: Fóssil | I6: Petróleo | J6: Registro | K6: Óleo Diesel | L6: 1998-09-11 | M6: 60 | N6: 60 | O6: 0 | P6: Não | Q6: -11.047991 | R6: -45.192991 | U6: 100% para Alcides Trento - (REG) | W6: Formosa do Rio Preto - BA
A7: 2026-10-01 | B7: Norfil Agro | C7: 000945 | D7: CGH.PH.BA.000945-8.1 | E7: BA | F7: CGH | G7: Operação | H7: Hídrica | I7: Potencial hidráulico | J7: Registro | K7: Potencial hidráulico | L7: 1990-01-01 | M7: 450 | N7: 450 | O7: 0 | P7: Não | Q7: -12.879247 | R7: -45.800474 | U7: 100% para NORFIL AGRO LTDA - 06.213.692/0001-32 (REG) | V7: 46 - Grande e outros - Sao Francisco | W7: São Desidério - BA
A8: 2026-10-01 | B8: Itapebi | C8: 001175 | D8: UHE.PH.BA.001175-4.1 | E8: BA | F8: UHE | G8: Operação | H8: Hídrica | I8: Potencial hidráulico | J8: Concessão | K8: Potencial hidráulico | L8: 2003-02-18 | M8: 462011 | N8: 462011 | O8: 202100 | P8: Não | Q8: -15.965643 | R8: -39.592639 | S8: 1999-05-28 | T8: 2039-05-18 | U8: 100% para ITAPEBI GERACAO DE ENERGIA SA - 02.397.080/0001-96 (PIE) | V8: 54 - Jequitinhonha | W8: Itapebi - BA
A9: 2026-10-01 | B9: Itapetinga | C9: 001178 | D9: UTE.PE.BA.001178-9.1 | E9: BA | F9: UTE | G9: Operação | H9: Fóssil | I9: Petróleo | J9: Registro | K9: Óleo Diesel | L9: 2008-07-01 | M9: 324 | N9: 324 | O9: 0 | P9: Não | Q9: -15.246167 | R9: -40.247381 | U9: 100% para REIZIGER PARTICIPACOES LTDA - 04.483.165/0001-12 (REG) | W9: Itapetinga - BA
A10: 2026-10-01 | B10: Paulo Afonso I | C10: 002012 | D10: UHE.PH.BA.002012-5.1 | E10: BA | F10: UHE | G10: Operação | H10: Hídrica | I10: Potencial hidráulico | J10: Concessão | K10: Potencial hidráulico | L10: 1964-12-30 | M10: 180001 | N10: 180001 | O10: 10 | P10: Não | Q10: -9.3981038 | R10: -38.202872 | S10: 2022-06-17 | T10: 2052-06-17 | U10: 100% para AXIA ENERGIA NORDESTE S.A. - 33.541.368/0001-16 (PIE) | V10: 49 - Sao Francisco, a jusante do Pajeu | W10: Delmiro Gouveia - AL, Paulo Afonso - BA
A11: 2026-10-01 | B11: Presidente Goulart | C11: 002146 | D11: PCH.PH.BA.002146-6.1 | E11: BA | F11: PCH | G11: Operação | H11: Hídrica | I11: Potencial hidráulico | J11: Concessão | K11: Potencial hidráulico | L11: 1963-12-31 | M11: 8000 | N11: 8000 | O11: 5210 | P11: Não | Q11: -13.338903 | R11: -44.633047 | S11: 1997-08-08 | T11: 2029-03-21 | U11: 100% para AFLUENTE GERACAO DE ENERGIA ELETRICA S.A. - 07.620.094/0001-40 (SP) | V11: 45 - Corrente e outros - Sao Francisco | W11: Correntina - BA
A12: 2026-10-01 | B12: Refinaria Landulpho Alves (RLAM) | C12: 002197 | D12: UTE.PE.BA.002197-0.1 | E12: BA | F12: UTE | G12: Operação | H12: Fóssil | I12: Petróleo | J12: Autorização | K12: Gás de Refinaria | L12: 2001-08-01 | M12: 62500 | N12: 62500 | O12: 0 | P12: Não | Q12: -12.62401 | R12: -38.670535 | S12: 1998-08-24 | T12: 2028-08-24 | U12: 100% para REFINARIA DE MATARIPE S.A. - 41.777.706/0001-41 (APE) | W12: São Francisco do Conde - BA
A13: 2026-10-01 | B13: Rieger Agropecuária | C13: 002271 | D13: CGH.PH.BA.002271-3.2 | E13: BA | F13: CGH | G13: Operação | H13: Hídrica | I13: Potencial hidráulico | J13: Registro | K13: Potencial hidráulico | L13: 1987-08-01 | M13: 3000 | N13: 3000 | O13: 0 | P13: Não | Q13: -12.452215 | R13: -45.190382 | U13: 100% para RIEGER AGROPECUARIA LTDA - 77.837.656/0001-98 (REG) | V13: 46 - Grande e outros - Sao Francisco | W13: São Desidério - BA
A14: 2026-10-01 | B14: Salvador | C14: 002683 | D14: UTE.RU.BA.002683-2.1 | E14: BA | F14: UTE | G14: Operação | H14: Biomassa | I14: Resíduos sólidos urbanos | J14: Autorização | K14: Biogás - RU | L14: 2010-12-22 | M14: 19730 | N14: 19730 | O14: 8500 | P14: Não | Q14: -12.860337 | R14: -38.352079 | S14: 2009-02-10 | T14: 2039-02-10 | U14: 100% para TERMOVERDE SALVADOR S.A. - 10.267.349/0001-48 (PIE) | W14: Salvador - BA
A15: 2026-10-01 | B15: Sítio Grande | C15: 002754 | D15: PCH.PH.BA.002754-5.1 | E15: BA | F15: PCH | G15: Operação | H15: Hídrica | I15: Potencial hidráulico | J15: Autorização | K15: Potencial hidráulico | L15: 2010-10-23 | M15: 25000 | N15: 25000 | O15: 18640 | P15: Não | Q15: -12.440829 | R15: -45.165558 | S15: 2010-10-23 | T15: 2047-10-27 | U15: 100% para BAHIA PCH I S.A. - 08.747.075/0001-42 (PIE) | V15: 46 - Grande e outros - Sao Francisco | W15: São Desidério - BA
A16: 2026-10-01 | B16: Sobradinho | C16: 002755 | D16: UHE.PH.BA.002755-3.1 | E16: BA | F16: UHE | G16: Operação | H16: Hídrica | I16: Potencial hidráulico | J16: Concessão | K16: Potencial hidráulico | L16: 1982-03-03 | M16: 1050300 | N16: 1050300 | O16: 504500 | P16: Não | Q16: -9.4302384 | R16: -40.827199 | S16: 2022-06-17 | T16: 2052-06-17 | U16: 100% para AXIA ENERGIA NORDESTE S.A. - 33.541.368/0001-16 (PIE) | V16: 47 - Salitre e outros - Sao Francisco | W16: Sobradinho - BA
A17: 2026-10-01 | B17: Funil | C17: 027046 | D17: UHE.PH.BA.027046-6.1 | E17: BA | F17: UHE | G17: Operação | H17: Hídrica | I17: Potencial hidráulico | J17: Concessão | K17: Potencial hidráulico | L17: 1970-02-13 | M17: 30000 | N17: 30000 | O17: 10910 | P17: Não | Q17: -14.229056 | R17: -39.462047 | S17: 2022-06-17 | T17: 2052-06-17 | U17: 100% para AXIA ENERGIA NORDESTE S.A. - 33.541.368/0001-16 (PIE) | V17: 52 - Contas | W17: Ubaitaba - BA
A18: 2026-10-01 | B18: Paulo Afonso II | C18: 027048 | D18: UHE.PH.BA.027048-2.1 | E18: BA | F18: UHE | G18: Operação | H18: Hídrica | I18: Potencial hidráulico | J18: Concessão | K18: Potencial hidráulico | L18: 1961-10-24 | M18: 443000 | N18: 443000 | O18: 10 | P18: Não | Q18: -9.3968831 | R18: -38.202663 | S18: 2022-06-17 | T18: 2052-06-17 | U18: 100% para AXIA ENERGIA NORDESTE S.A. - 33.541.368/0001-16 (PIE) | V18: 49 - Sao Francisco, a jusante do Pajeu | W18: Delmiro Gouveia - AL, Paulo Afonso - BA
